Workbook

Sheet README
A1: Loan Recommendation Lab (educational)
A3: 80 loan applicants, their credit history, and 4 fictional loan products. Amounts in VND.
A4: Sheets applicants, history and products are the data. Sheets task1 to task5 hold one reference solution each, as Excel formulas.
A5: Score bands follow the 300-850 CIC scale. Product rules, rates and limits are invented for teaching and are not any lender's policy.

Sheet applicants
A1: applicant_id | B1: monthly_income | C1: existing_installments | D1: credit_score | E1: requested_amount | F1: requested_term
A2: 5001 | B2: 17500000 | C2: 0 | D2: 426 | E2: 131000000 | F2: 12
A3: 5002 | B3: 11000000 | C3: 4200000 | D3: 799 | E3: 29000000 | F3: 24
A4: 5003 | B4: 7000000 | C4: 0 | E4: 51000000 | F4: 12
A5: 5004 | B5: 20000000 | C5: 0 | D5: 710 | E5: 88000000 | F5: 24
A6: 5005 | B6: 20500000 | C6: 2200000 | E6: 110000000 | F6: 18
A7: 5006 | B7: 17500000 | C7: 0 | E7: 62000000 | F7: 48
A8: 5007 | B8: 8500000 | C8: 2100000 | D8: 779 | E8: 84000000 | F8: 24
A9: 5008 | B9: 11000000 | C9: 3000000 | D9: 599 | E9: 55000000 | F9: 36
A10: 5009 | B10: 11000000 | C10: 2700000 | D10: 468 | E10: 120000000 | F10: 18
A11: 5010 | B11: 7000000 | C11: 600000 | D11: 660 | E11: 32000000 | F11: 6
A12: 5011 | B12: 6000000 | C12: 0 | E12: 60000000 | F12: 12
A13: 5012 | B13: 17500000 | C13: 5800000 | E13: 166000000 | F13: 6
A14: 5013 | B14: 24000000 | C14: 7600000 | D14: 518 | E14: 111000000 | F14: 48
A15: 5014 | B15: 12500000 | C15: 0 | E15: 52000000 | F15: 24
A16: 5015 | B16: 9500000 | C16: 0 | D16: 442 | E16: 82000000 | F16: 12
A17: 5016 | B17: 26000000 | C17: 0 | E17: 200000000 | F17: 24
A18: 5017 | B18: 6000000 | C18: 0 | E18: 50000000 | F18: 48
A19: 5018 | B19: 14500000 | C19: 3600000 | D19: 631 | E19: 49000000 | F19: 6
A20: 5019 | B20: 21000000 | C20: 1300000 | D20: 699 | E20: 189000000 | F20: 48
A21: 5020 | B21: 26000000 | C21: 5100000 | E21: 191000000 | F21: 48
A22: 5021 | B22: 8500000 | C22: 3100000 | D22: 577 | E22: 33000000 | F22: 36
A23: 5022 | B23: 9500000 | C23: 1500000 | D23: 564 | E23: 45000000 | F23: 36
A24: 5023 | B24: 6000000 | C24: 0 | E24: 45000000 | F24: 48
A25: 5024 | B25: 45000000 | C25: 0 | D25: 760 | E25: 200000000 | F25: 6
A26: 5025 | B26: 13000000 | C26: 0 | D26: 563 | E26: 133000000 | F26: 6
A27: 5026 | B27: 4500000 | C27: 0 | D27: 642 | E27: 32000000 | F27: 12
A28: 5027 | B28: 10000000 | C28: 3300000 | E28: 48000000 | F28: 24
A29: 5028 | B29: 23000000 | C29: 0 | D29: 687 | E29: 154000000 | F29: 24
A30: 5029 | B30: 7500000 | C30: 2100000 | E30: 27000000 | F30: 48
A31: 5030 | B31: 15500000 | C31: 4000000 | D31: 628 | E31: 112000000 | F31: 12
A32: 5031 | B32: 8500000 | C32: 1500000 | D32: 723 | E32: 45000000 | F32: 36
A33: 5032 | B33: 4500000 | C33: 0 | D33: 842 | E33: 35000000 | F33: 36
A34: 5033 | B34: 18500000 | C34: 4700000 | D34: 413 | E34: 146000000 | F34: 48
A35: 5034 | B35: 14500000 | C35: 5500000 | D35: 840 | E35: 50000000 | F35: 24
A36: 5035 | B36: 9000000 | C36: 0 | E36: 48000000 | F36: 24
A37: 5036 | B37: 11000000 | C37: 2900000 | D37: 562 | E37: 114000000 | F37: 12
A38: 5037 | B38: 10000000 | C38: 1900000 | D38: 600 | E38: 65000000 | F38: 12
A39: 5038 | B39: 6500000 | C39: 700000 | D39: 818 | E39: 17000000 | F39: 36
A40: 5039 | B40: 9500000 | C40: 0 | D40: 612 | E40: 33000000 | F40: 12
...

Sheet history
A1: history_id | B1: applicant_id | C1: product_type | D1: opened | E1: amount | F1: max_dpd | G1: status
A2: 7001 | B2: 5037 | C2: Motorbike loan | D2: 44567 | E2: 31000000 | F2: 3 | G2: closed
A3: 7002 | B3: 5051 | C3: Personal loan | D3: 44591 | E3: 21000000 | F3: 8 | G3: active
A4: 7003 | B4: 5034 | C4: Personal loan | D4: 44614 | E4: 51000000 | F4: 7 | G4: active
A5: 7004 | B5: 5061 | C5: Motorbike loan | D5: 44615 | E5: 40000000 | F5: 90 | G5: closed
A6: 7005 | B6: 5038 | C6: Appliance installment | D6: 44616 | E6: 33000000 | F6: 0 | G6: closed
A7: 7006 | B7: 5025 | C7: Personal loan | D7: 44622 | E7: 47000000 | F7: 68 | G7: closed
A8: 7007 | B8: 5032 | C8: Credit card | D8: 44623 | E8: 61000000 | F8: 8 | G8: active
A9: 7008 | B9: 5039 | C9: Credit card | D9: 44623 | E9: 48000000 | F9: 7 | G9: active
A10: 7009 | B10: 5039 | C10: Personal loan | D10: 44624 | E10: 16000000 | F10: 4 | G10: closed
A11: 7010 | B11: 5058 | C11: Credit card | D11: 44634 | E11: 21000000 | F11: 3 | G11: closed
A12: 7011 | B12: 5072 | C12: Motorbike loan | D12: 44639 | E12: 46000000 | F12: 6 | G12: closed
A13: 7012 | B13: 5076 | C13: Appliance installment | D13: 44647 | E13: 79000000 | F13: 2 | G13: closed
... A152: 7151 | B152: 5074 | C152: Motorbike loan | D152: 45962 | E152: 72000000 | F152: 9 | G152: closed

Sheet products
A1: product_id | B1: name | C1: min_score | D1: min_income | E1: max_amount | F1: max_term | G1: flat_rate | H1: max_dti | I1: thin_file_ok
A2: 1 | B2: Prime | C2: 700 | D2: 15000000 | E2: 300000000 | F2: 48 | G2: 0.1 | H2: 0.5 | I2: 0
A3: 2 | B3: Standard | C3: 600 | D3: 10000000 | E3: 150000000 | F3: 36 | G3: 0.16 | H3: 0.45 | I3: 0
A4: 3 | B4: Starter | C4: 500 | D4: 7000000 | E4: 50000000 | F4: 24 | G4: 0.24 | H4: 0.4 | I4: 0
A5: 4 | B5: Micro | C5: 400 | D5: 5000000 | E5: 15000000 | F5: 12 | G5: 0.3 | H5: 0.35 | I5: 1

Sheet task1
A1: band | B1: min_score | C1: max_score | D1: applicants | E1: avg_income
A2: High | B2: 701 | C2: 850 | D2: =COUNTIFS(applicants!$D$2:$D$81,">="&B2,applicants!$D$2:$D$81,"<="&C2) -> 23 | E2: =ROUND(AVERAGEIFS(applicants!$B$2:$B$81,applicants!$D$2:$D$81,">="&B2,applicants!$D$2:$D$81,"<="&C2),0) -> 14695652
A3: Medium | B3: 501 | C3: 700 | D3: =COUNTIFS(applicants!$D$2:$D$81,">="&B3,applicants!$D$2:$D$81,"<="&C3) -> 27 | E3: =ROUND(AVERAGEIFS(applicants!$B$2:$B$81,applicants!$D$2:$D$81,">="&B3,applicants!$D$2:$D$81,"<="&C3),0) -> 14814815
A4: Low | B4: 300 | C4: 500 | D4: =COUNTIFS(applicants!$D$2:$D$81,">="&B4,applicants!$D$2:$D$81,"<="&C4) -> 10 | E4: =ROUND(AVERAGEIFS(applicants!$B$2:$B$81,applicants!$D$2:$D$81,">="&B4,applicants!$D$2:$D$81,"<="&C4),0) -> 14800000
A5: No score | D5: =COUNTIFS(applicants!$D$2:$D$81,"=") -> 20 | E5: =ROUND(AVERAGEIFS(applicants!$B$2:$B$81,applicants!$D$2:$D$81,"="),0) -> 13000000

Sheet task2
A1: applicant_id | B1: credit_score | C1: worst_dpd | D1: history_class | F1: history_class | G1: applicants | H1: avg_score
A2: 5001 | B2: 426 | C2: =IF(COUNTIF(history!$B$2:$B$152,A2)=0,"",_xlfn.MAXIFS(history!$F$2:$F$152,history!$B$2:$B$152,A2)) -> 262 | D2: =IF(C2="","No history",IF(C2>=91,"Severe",IF(C2>=10,"Watch","Clean"))) -> Severe | F2: No history | G2: =COUNTIF($D$2:$D$81,F2) -> 20 | H2: =IFERROR(ROUND(AVERAGEIFS($B$2:$B$81,$D$2:$D$81,F2),0),"")
A3: 5002 | B3: 799 | C3: =IF(COUNTIF(history!$B$2:$B$152,A3)=0,"",_xlfn.MAXIFS(history!$F$2:$F$152,history!$B$2:$B$152,A3)) -> 7 | D3: =IF(C3="","No history",IF(C3>=91,"Severe",IF(C3>=10,"Watch","Clean"))) -> Clean | F3: Clean | G3: =COUNTIF($D$2:$D$81,F3) -> 36 | H3: =IFERROR(ROUND(AVERAGEIFS($B$2:$B$81,$D$2:$D$81,F3),0),"") -> 710
A4: 5003 | C4: =IF(COUNTIF(history!$B$2:$B$152,A4)=0,"",_xlfn.MAXIFS(history!$F$2:$F$152,history!$B$2:$B$152,A4)) | D4: =IF(C4="","No history",IF(C4>=91,"Severe",IF(C4>=10,"Watch","Clean"))) -> No history | F4: Watch | G4: =COUNTIF($D$2:$D$81,F4) -> 15 | H4: =IFERROR(ROUND(AVERAGEIFS($B$2:$B$81,$D$2:$D$81,F4),0),"") -> 578
A5: 5004 | B5: 710 | C5: =IF(COUNTIF(history!$B$2:$B$152,A5)=0,"",_xlfn.MAXIFS(history!$F$2:$F$152,history!$B$2:$B$152,A5)) -> 91 | D5: =IF(C5="","No history",IF(C5>=91,"Severe",IF(C5>=10,"Watch","Clean"))) -> Severe | F5: Severe | G5: =COUNTIF($D$2:$D$81,F5) -> 9 | H5: =IFERROR(ROUND(AVERAGEIFS($B$2:$B$81,$D$2:$D$81,F5),0),"") -> 440
A6: 5005 | C6: =IF(COUNTIF(history!$B$2:$B$152,A6)=0,"",_xlfn.MAXIFS(history!$F$2:$F$152,history!$B$2:$B$152,A6)) | D6: =IF(C6="","No history",IF(C6>=91,"Severe",IF(C6>=10,"Watch","Clean"))) -> No history
A7: 5006 | C7: =IF(COUNTIF(history!$B$2:$B$152,A7)=0,"",_xlfn.MAXIFS(history!$F$2:$F$152,history!$B$2:$B$152,A7)) | D7: =IF(C7="","No history",IF(C7>=91,"Severe",IF(C7>=10,"Watch","Clean"))) -> No history
A8: 5007 | B8: 779 | C8: =IF(COUNTIF(history!$B$2:$B$152,A8)=0,"",_xlfn.MAXIFS(history!$F$2:$F$152,history!$B$2:$B$152,A8)) -> 9 | D8: =IF(C8="","No history",IF(C8>=91,"Severe",IF(C8>=10,"Watch","Clean"))) -> Clean
A9: 5008 | B9: 599 | C9: =IF(COUNTIF(history!$B$2:$B$152,A9)=0,"",_xlfn.MAXIFS(history!$F$2:$F$152,history!$B$2:$B$152,A9)) -> 6 | D9: =IF(C9="","No history",IF(C9>=91,"Severe",IF(C9>=10,"Watch","Clean"))) -> Clean
A10: 5009 | B10: 468 | C10: =IF(COUNTIF(history!$B$2:$B$152,A10)=0,"",_xlfn.MAXIFS(history!$F$2:$F$152,history!$B$2:$B$152,A10)) -> 325 | D10: =IF(C10="","No history",IF(C10>=91,"Severe",IF(C10>=10,"Watch","Clean"))) -> Severe
A11: 5010 | B11: 660 | C11: =IF(COUNTIF(history!$B$2:$B$152,A11)=0,"",_xlfn.MAXIFS(history!$F$2:$F$152,history!$B$2:$B$152,A11)) -> 36 | D11: =IF(C11="","No history",IF(C11>=91,"Severe",IF(C11>=10,"Watch","Clean"))) -> Watch
A12: 5011 | C12: =IF(COUNTIF(history!$B$2:$B$152,A12)=0,"",_xlfn.MAXIFS(history!$F$2:$F$152,history!$B$2:$B$152,A12)) | D12: =IF(C12="","No history",IF(C12>=91,"Severe",IF(C12>=10,"Watch","Clean"))) -> No history
A13: 5012 | C13: =IF(COUNTIF(history!$B$2:$B$152,A13)=0,"",_xlfn.MAXIFS(history!$F$2:$F$152,history!$B$2:$B$152,A13)) | D13: =IF(C13="","No history",IF(C13>=91,"Severe",IF(C13>=10,"Watch","Clean"))) -> No history
A14: 5013 | B14: 518 | C14: =IF(COUNTIF(history!$B$2:$B$152,A14)=0,"",_xlfn.MAXIFS(history!$F$2:$F$152,history!$B$2:$B$152,A14)) -> 65 | D14: =IF(C14="","No history",IF(C14>=91,"Severe",IF(C14>=10,"Watch","Clean"))) -> Watch
A15: 5014 | C15: =IF(COUNTIF(history!$B$2:$B$152,A15)=0,"",_xlfn.MAXIFS(history!$F$2:$F$152,history!$B$2:$B$152,A15)) | D15: =IF(C15="","No history",IF(C15>=91,"Severe",IF(C15>=10,"Watch","Clean"))) -> No history
A16: 5015 | B16: 442 | C16: =IF(COUNTIF(history!$B$2:$B$152,A16)=0,"",_xlfn.MAXIFS(history!$F$2:$F$152,history!$B$2:$B$152,A16)) -> 183 | D16: =IF(C16="","No history",IF(C16>=91,"Severe",IF(C16>=10,"Watch","Clean"))) -> Severe
A17: 5016 | C17: =IF(COUNTIF(history!$B$2:$B$152,A17)=0,"",_xlfn.MAXIFS(history!$F$2:$F$152,history!$B$2:$B$152,A17)) | D17: =IF(C17="","No history",IF(C17>=91,"Severe",IF(C17>=10,"Watch","Clean"))) -> No history
A18: 5017 | C18: =IF(COUNTIF(history!$B$2:$B$152,A18)=0,"",_xlfn.MAXIFS(history!$F$2:$F$152,history!$B$2:$B$152,A18)) | D18: =IF(C18="","No history",IF(C18>=91,"Severe",IF(C18>=10,"Watch","Clean"))) -> No history
A19: 5018 | B19: 631 | C19: =IF(COUNTIF(history!$B$2:$B$152,A19)=0,"",_xlfn.MAXIFS(history!$F$2:$F$152,history!$B$2:$B$152,A19)) -> 6 | D19: =IF(C19="","No history",IF(C19>=91,"Severe",IF(C19>=10,"Watch","Clean"))) -> Clean
A20: 5019 | B20: 699 | C20: =IF(COUNTIF(history!$B$2:$B$152,A20)=0,"",_xlfn.MAXIFS(history!$F$2:$F$152,history!$B$2:$B$152,A20)) -> 8 | D20: =IF(C20="","No history",IF(C20>=91,"Severe",IF(C20>=10,"Watch","Clean"))) -> Clean
A21: 5020 | C21: =IF(COUNTIF(history!$B$2:$B$152,A21)=0,"",_xlfn.MAXIFS(history!$F$2:$F$152,history!$B$2:$B$152,A21)) | D21: =IF(C21="","No history",IF(C21>=91,"Severe",IF(C21>=10,"Watch","Clean"))) -> No history
A22: 5021 | B22: 577 | C22: =IF(COUNTIF(history!$B$2:$B$152,A22)=0,"",_xlfn.MAXIFS(history!$F$2:$F$152,history!$B$2:$B$152,A22)) -> 77 | D22: =IF(C22="","No history",IF(C22>=91,"Severe",IF(C22>=10,"Watch","Clean"))) -> Watch
A23: 5022 | B23: 564 | C23: =IF(COUNTIF(history!$B$2:$B$152,A23)=0,"",_xlfn.MAXIFS(history!$F$2:$F$152,history!$B$2:$B$152,A23)) -> 9 | D23: =IF(C23="","No history",IF(C23>=91,"Severe",IF(C23>=10,"Watch","Clean"))) -> Clean
A24: 5023 | C24: =IF(COUNTIF(history!$B$2:$B$152,A24)=0,"",_xlfn.MAXIFS(history!$F$2:$F$152,history!$B$2:$B$152,A24)) | D24: =IF(C24="","No history",IF(C24>=91,"Severe",IF(C24>=10,"Watch","Clean"))) -> No history
A25: 5024 | B25: 760 | C25: =IF(COUNTIF(history!$B$2:$B$152,A25)=0,"",_xlfn.MAXIFS(history!$F$2:$F$152,history!$B$2:$B$152,A25)) -> 3 | D25: =IF(C25="","No history",IF(C25>=91,"Severe",IF(C25>=10,"Watch","Clean"))) -> Clean
A26: 5025 | B26: 563 | C26: =IF(COUNTIF(history!$B$2:$B$152,A26)=0,"",_xlfn.MAXIFS(history!$F$2:$F$152,history!$B$2:$B$152,A26)) -> 68 | D26: =IF(C26="","No history",IF(C26>=91,"Severe",IF(C26>=10,"Watch","Clean"))) -> Watch
A27: 5026 | B27: 642 | C27: =IF(COUNTIF(history!$B$2:$B$152,A27)=0,"",_xlfn.MAXIFS(history!$F$2:$F$152,history!$B$2:$B$152,A27)) -> 6 | D27: =IF(C27="","No history",IF(C27>=91,"Severe",IF(C27>=10,"Watch","Clean"))) -> Clean
A28: 5027 | C28: =IF(COUNTIF(history!$B$2:$B$152,A28)=0,"",_xlfn.MAXIFS(history!$F$2:$F$152,history!$B$2:$B$152,A28)) | D28: =IF(C28="","No history",IF(C28>=91,"Severe",IF(C28>=10,"Watch","Clean"))) -> No history
A29: 5028 | B29: 687 | C29: =IF(COUNTIF(history!$B$2:$B$152,A29)=0,"",_xlfn.MAXIFS(history!$F$2:$F$152,history!$B$2:$B$152,A29)) -> 4 | D29: =IF(C29="","No history",IF(C29>=91,"Severe",IF(C29>=10,"Watch","Clean"))) -> Clean
A30: 5029 | C30: =IF(COUNTIF(history!$B$2:$B$152,A30)=0,"",_xlfn.MAXIFS(history!$F$2:$F$152,history!$B$2:$B$152,A30)) | D30: =IF(C30="","No history",IF(C30>=91,"Severe",IF(C30>=10,"Watch","Clean"))) -> No history
A31: 5030 | B31: 628 | C31: =IF(COUNTIF(history!$B$2:$B$152,A31)=0,"",_xlfn.MAXIFS(history!$F$2:$F$152,history!$B$2:$B$152,A31)) -> 72 | D31: =IF(C31="","No history",IF(C31>=91,"Severe",IF(C31>=10,"Watch","Clean"))) -> Watch
A32: 5031 | B32: 723 | C32: =IF(COUNTIF(history!$B$2:$B$152,A32)=0,"",_xlfn.MAXIFS(history!$F$2:$F$152,history!$B$2:$B$152,A32)) -> 8 | D32: =IF(C32="","No history",IF(C32>=91,"Severe",IF(C32>=10,"Watch","Clean"))) -> Clean
A33: 5032 | B33: 842 | C33: =IF(COUNTIF(history!$B$2:$B$152,A33)=0,"",_xlfn.MAXIFS(history!$F$2:$F$152,history!$B$2:$B$152,A33)) -> 8 | D33: =IF(C33="","No history",IF(C33>=91,"Severe",IF(C33>=10,"Watch","Clean"))) -> Clean
A34: 5033 | B34: 413 | C34: =IF(COUNTIF(history!$B$2:$B$152,A34)=0,"",_xlfn.MAXIFS(history!$F$2:$F$152,history!$B$2:$B$152,A34)) -> 339 | D34: =IF(C34="","No history",IF(C34>=91,"Severe",IF(C34>=10,"Watch","Clean"))) -> Severe
A35: 5034 | B35: 840 | C35: =IF(COUNTIF(history!$B$2:$B$152,A35)=0,"",_xlfn.MAXIFS(history!$F$2:$F$152,history!$B$2:$B$152,A35)) -> 7 | D35: =IF(C35="","No history",IF(C35>=91,"Severe",IF(C35>=10,"Watch","Clean"))) -> Clean
A36: 5035 | C36: =IF(COUNTIF(history!$B$2:$B$152,A36)=0,"",_xlfn.MAXIFS(history!$F$2:$F$152,history!$B$2:$B$152,A36)) | D36: =IF(C36="","No history",IF(C36>=91,"Severe",IF(C36>=10,"Watch","Clean"))) -> No history
A37: 5036 | B37: 562 | C37: =IF(COUNTIF(history!$B$2:$B$152,A37)=0,"",_xlfn.MAXIFS(history!$F$2:$F$152,history!$B$2:$B$152,A37)) -> 37 | D37: =IF(C37="","No history",IF(C37>=91,"Severe",IF(C37>=10,"Watch","Clean"))) -> Watch
A38: 5037 | B38: 600 | C38: =IF(COUNTIF(history!$B$2:$B$152,A38)=0,"",_xlfn.MAXIFS(history!$F$2:$F$152,history!$B$2:$B$152,A38)) -> 7 | D38: =IF(C38="","No history",IF(C38>=91,"Severe",IF(C38>=10,"Watch","Clean"))) -> Clean
A39: 5038 | B39: 818 | C39: =IF(COUNTIF(history!$B$2:$B$152,A39)=0,"",_xlfn.MAXIFS(history!$F$2:$F$152,history!$B$2:$B$152,A39)) -> 2 | D39: =IF(C39="","No history",IF(C39>=91,"Severe",IF(C39>=10,"Watch","Clean"))) -> Clean
A40: 5039 | B40: 612 | C40: =IF(COUNTIF(history!$B$2:$B$152,A40)=0,"",_xlfn.MAXIFS(history!$F$2:$F$152,history!$B$2:$B$152,A40)) -> 17 | D40: =IF(C40="","No history",IF(C40>=91,"Severe",IF(C40>=10,"Watch","Clean"))) -> Watch
...

Sheet task3
A1: applicant_id | B1: credit_score | C1: monthly_income | D1: worst_dpd | F1: product_id | G1: product | H1: eligible_applicants
A2: 5001 | B2: 426 | C2: 17500000 | D2: 262 | F2: 1 | G2: =INDEX(products!$B$2:$B$5,F2) -> Prime | H2: =COUNTIFS($B$2:$B$81,">="&INDEX(products!$C$2:$C$5,F2),$C$2:$C$81,">="&INDEX(products!$D$2:$D$5,F2),$D$2:$D$81,"<=90")+INDEX(products!$I$2:$I$5,F2)*(COUNTIFS($C$2:$C$81,">="&INDEX(products!$D$2:$D$5,F2),$D$2:$D$81,"<=90")-COUNTIFS($B$2:$B$81,">=0",$C$2:$C$81,">="&INDEX(products!$D$2:$D$5,F2),$D$2:$D$81,"<=90")) -> 10
A3: 5002 | B3: 799 | C3: 11000000 | D3: 7 | F3: 2 | G3: =INDEX(products!$B$2:$B$5,F3) -> Standard | H3: =COUNTIFS($B$2:$B$81,">="&INDEX(products!$C$2:$C$5,F3),$C$2:$C$81,">="&INDEX(products!$D$2:$D$5,F3),$D$2:$D$81,"<=90")+INDEX(products!$I$2:$I$5,F3)*(COUNTIFS($C$2:$C$81,">="&INDEX(products!$D$2:$D$5,F3),$D$2:$D$81,"<=90")-COUNTIFS($B$2:$B$81,">=0",$C$2:$C$81,">="&INDEX(products!$D$2:$D$5,F3),$D$2:$D$81,"<=90")) -> 26
A4: 5003 | C4: 7000000 | D4: 0 | F4: 3 | G4: =INDEX(products!$B$2:$B$5,F4) -> Starter | H4: =COUNTIFS($B$2:$B$81,">="&INDEX(products!$C$2:$C$5,F4),$C$2:$C$81,">="&INDEX(products!$D$2:$D$5,F4),$D$2:$D$81,"<=90")+INDEX(products!$I$2:$I$5,F4)*(COUNTIFS($C$2:$C$81,">="&INDEX(products!$D$2:$D$5,F4),$D$2:$D$81,"<=90")-COUNTIFS($B$2:$B$81,">=0",$C$2:$C$81,">="&INDEX(products!$D$2:$D$5,F4),$D$2:$D$81,"<=90")) -> 47
A5: 5004 | B5: 710 | C5: 20000000 | D5: 91 | F5: 4 | G5: =INDEX(products!$B$2:$B$5,F5) -> Micro | H5: =COUNTIFS($B$2:$B$81,">="&INDEX(products!$C$2:$C$5,F5),$C$2:$C$81,">="&INDEX(products!$D$2:$D$5,F5),$D$2:$D$81,"<=90")+INDEX(products!$I$2:$I$5,F5)*(COUNTIFS($C$2:$C$81,">="&INDEX(products!$D$2:$D$5,F5),$D$2:$D$81,"<=90")-COUNTIFS($B$2:$B$81,">=0",$C$2:$C$81,">="&INDEX(products!$D$2:$D$5,F5),$D$2:$D$81,"<=90")) -> 69
A6: 5005 | C6: 20500000 | D6: 0
A7: 5006 | C7: 17500000 | D7: 0
A8: 5007 | B8: 779 | C8: 8500000 | D8: 9
A9: 5008 | B9: 599 | C9: 11000000 | D9: 6
A10: 5009 | B10: 468 | C10: 11000000 | D10: 325
A11: 5010 | B11: 660 | C11: 7000000 | D11: 36
A12: 5011 | C12: 6000000 | D12: 0
A13: 5012 | C13: 17500000 | D13: 0
A14: 5013 | B14: 518 | C14: 24000000 | D14: 65
A15: 5014 | C15: 12500000 | D15: 0
A16: 5015 | B16: 442 | C16: 9500000 | D16: 183
A17: 5016 | C17: 26000000 | D17: 0
A18: 5017 | C18: 6000000 | D18: 0
A19: 5018 | B19: 631 | C19: 14500000 | D19: 6
A20: 5019 | B20: 699 | C20: 21000000 | D20: 8
A21: 5020 | C21: 26000000 | D21: 0
A22: 5021 | B22: 577 | C22: 8500000 | D22: 77
A23: 5022 | B23: 564 | C23: 9500000 | D23: 9
A24: 5023 | C24: 6000000 | D24: 0
A25: 5024 | B25: 760 | C25: 45000000 | D25: 3
A26: 5025 | B26: 563 | C26: 13000000 | D26: 68
A27: 5026 | B27: 642 | C27: 4500000 | D27: 6
A28: 5027 | C28: 10000000 | D28: 0
A29: 5028 | B29: 687 | C29: 23000000 | D29: 4
A30: 5029 | C30: 7500000 | D30: 0
A31: 5030 | B31: 628 | C31: 15500000 | D31: 72
A32: 5031 | B32: 723 | C32: 8500000 | D32: 8
A33: 5032 | B33: 842 | C33: 4500000 | D33: 8
A34: 5033 | B34: 413 | C34: 18500000 | D34: 339
A35: 5034 | B35: 840 | C35: 14500000 | D35: 7
A36: 5035 | C36: 9000000 | D36: 0
A37: 5036 | B37: 562 | C37: 11000000 | D37: 37
A38: 5037 | B38: 600 | C38: 10000000 | D38: 7
A39: 5038 | B39: 818 | C39: 6500000 | D39: 2
A40: 5039 | B40: 612 | C40: 9500000 | D40: 17
...

Sheet task4
A1: applicant_id | B1: credit_score | C1: monthly_income | D1: worst_dpd | E1: Prime | F1: Standard | G1: Starter | H1: Micro | I1: recommended | K1: recommended_product | L1: applicants
A2: 5001 | B2: 426 | C2: 17500000 | D2: 262 | E2: =IF(AND($D2<=90,$C2>=INDEX(products!$D$2:$D$5,MATCH(E$1,products!$B$2:$B$5,0)),OR($B2>=INDEX(products!$C$2:$C$5,MATCH(E$1,products!$B$2:$B$5,0)),AND($B2="",INDEX(products!$I$2:$I$5,MATCH(E$1,products!$B$2:$B$5,0))=1))),1,0) -> 0 | F2: =IF(AND($D2<=90,$C2>=INDEX(products!$D$2:$D$5,MATCH(F$1,products!$B$2:$B$5,0)),OR($B2>=INDEX(products!$C$2:$C$5,MATCH(F$1,products!$B$2:$B$5,0)),AND($B2="",INDEX(products!$I$2:$I$5,MATCH(F$1,products!$B$2:$B$5,0))=1))),1,0) -> 0 | G2: =IF(AND($D2<=90,$C2>=INDEX(products!$D$2:$D$5,MATCH(G$1,products!$B$2:$B$5,0)),OR($B2>=INDEX(products!$C$2:$C$5,MATCH(G$1,products!$B$2:$B$5,0)),AND($B2="",INDEX(products!$I$2:$I$5,MATCH(G$1,products!$B$2:$B$5,0))=1))),1,0) -> 0 | H2: =IF(AND($D2<=90,$C2>=INDEX(products!$D$2:$D$5,MATCH(H$1,products!$B$2:$B$5,0)),OR($B2>=INDEX(products!$C$2:$C$5,MATCH(H$1,products!$B$2:$B$5,0)),AND($B2="",INDEX(products!$I$2:$I$5,MATCH(H$1,products!$B$2:$B$5,0))=1))),1,0) -> 0 | I2: =IFERROR(INDEX($E$1:$H$1,MATCH(1,E2:H2,0)),"No offer") -> No offer | K2: Prime | L2: =COUNTIF($I$2:$I$81,K2) -> 10
A3: 5002 | B3: 799 | C3: 11000000 | D3: 7 | E3: =IF(AND($D3<=90,$C3>=INDEX(products!$D$2:$D$5,MATCH(E$1,products!$B$2:$B$5,0)),OR($B3>=INDEX(products!$C$2:$C$5,MATCH(E$1,products!$B$2:$B$5,0)),AND($B3="",INDEX(products!$I$2:$I$5,MATCH(E$1,products!$B$2:$B$5,0))=1))),1,0) -> 0 | F3: =IF(AND($D3<=90,$C3>=INDEX(products!$D$2:$D$5,MATCH(F$1,products!$B$2:$B$5,0)),OR($B3>=INDEX(products!$C$2:$C$5,MATCH(F$1,products!$B$2:$B$5,0)),AND($B3="",INDEX(products!$I$2:$I$5,MATCH(F$1,products!$B$2:$B$5,0))=1))),1,0) -> 1 | G3: =IF(AND($D3<=90,$C3>=INDEX(products!$D$2:$D$5,MATCH(G$1,products!$B$2:$B$5,0)),OR($B3>=INDEX(products!$C$2:$C$5,MATCH(G$1,products!$B$2:$B$5,0)),AND($B3="",INDEX(products!$I$2:$I$5,MATCH(G$1,products!$B$2:$B$5,0))=1))),1,0) -> 1 | H3: =IF(AND($D3<=90,$C3>=INDEX(products!$D$2:$D$5,MATCH(H$1,products!$B$2:$B$5,0)),OR($B3>=INDEX(products!$C$2:$C$5,MATCH(H$1,products!$B$2:$B$5,0)),AND($B3="",INDEX(products!$I$2:$I$5,MATCH(H$1,products!$B$2:$B$5,0))=1))),1,0) -> 1 | I3: =IFERROR(INDEX($E$1:$H$1,MATCH(1,E3:H3,0)),"No offer") -> Standard | K3: Standard | L3: =COUNTIF($I$2:$I$81,K3) -> 16
A4: 5003 | C4: 7000000 | D4: 0 | E4: =IF(AND($D4<=90,$C4>=INDEX(products!$D$2:$D$5,MATCH(E$1,products!$B$2:$B$5,0)),OR($B4>=INDEX(products!$C$2:$C$5,MATCH(E$1,products!$B$2:$B$5,0)),AND($B4="",INDEX(products!$I$2:$I$5,MATCH(E$1,products!$B$2:$B$5,0))=1))),1,0) -> 0 | F4: =IF(AND($D4<=90,$C4>=INDEX(products!$D$2:$D$5,MATCH(F$1,products!$B$2:$B$5,0)),OR($B4>=INDEX(products!$C$2:$C$5,MATCH(F$1,products!$B$2:$B$5,0)),AND($B4="",INDEX(products!$I$2:$I$5,MATCH(F$1,products!$B$2:$B$5,0))=1))),1,0) -> 0 | G4: =IF(AND($D4<=90,$C4>=INDEX(products!$D$2:$D$5,MATCH(G$1,products!$B$2:$B$5,0)),OR($B4>=INDEX(products!$C$2:$C$5,MATCH(G$1,products!$B$2:$B$5,0)),AND($B4="",INDEX(products!$I$2:$I$5,MATCH(G$1,products!$B$2:$B$5,0))=1))),1,0) -> 0 | H4: =IF(AND($D4<=90,$C4>=INDEX(products!$D$2:$D$5,MATCH(H$1,products!$B$2:$B$5,0)),OR($B4>=INDEX(products!$C$2:$C$5,MATCH(H$1,products!$B$2:$B$5,0)),AND($B4="",INDEX(products!$I$2:$I$5,MATCH(H$1,products!$B$2:$B$5,0))=1))),1,0) -> 1 | I4: =IFERROR(INDEX($E$1:$H$1,MATCH(1,E4:H4,0)),"No offer") -> Micro | K4: Starter | L4: =COUNTIF($I$2:$I$81,K4) -> 21
A5: 5004 | B5: 710 | C5: 20000000 | D5: 91 | E5: =IF(AND($D5<=90,$C5>=INDEX(products!$D$2:$D$5,MATCH(E$1,products!$B$2:$B$5,0)),OR($B5>=INDEX(products!$C$2:$C$5,MATCH(E$1,products!$B$2:$B$5,0)),AND($B5="",INDEX(products!$I$2:$I$5,MATCH(E$1,products!$B$2:$B$5,0))=1))),1,0) -> 0 | F5: =IF(AND($D5<=90,$C5>=INDEX(products!$D$2:$D$5,MATCH(F$1,products!$B$2:$B$5,0)),OR($B5>=INDEX(products!$C$2:$C$5,MATCH(F$1,products!$B$2:$B$5,0)),AND($B5="",INDEX(products!$I$2:$I$5,MATCH(F$1,products!$B$2:$B$5,0))=1))),1,0) -> 0 | G5: =IF(AND($D5<=90,$C5>=INDEX(products!$D$2:$D$5,MATCH(G$1,products!$B$2:$B$5,0)),OR($B5>=INDEX(products!$C$2:$C$5,MATCH(G$1,products!$B$2:$B$5,0)),AND($B5="",INDEX(products!$I$2:$I$5,MATCH(G$1,products!$B$2:$B$5,0))=1))),1,0) -> 0 | H5: =IF(AND($D5<=90,$C5>=INDEX(products!$D$2:$D$5,MATCH(H$1,products!$B$2:$B$5,0)),OR($B5>=INDEX(products!$C$2:$C$5,MATCH(H$1,products!$B$2:$B$5,0)),AND($B5="",INDEX(products!$I$2:$I$5,MATCH(H$1,products!$B$2:$B$5,0))=1))),1,0) -> 0 | I5: =IFERROR(INDEX($E$1:$H$1,MATCH(1,E5:H5,0)),"No offer") -> No offer | K5: Micro | L5: =COUNTIF($I$2:$I$81,K5) -> 22
A6: 5005 | C6: 20500000 | D6: 0 | E6: =IF(AND($D6<=90,$C6>=INDEX(products!$D$2:$D$5,MATCH(E$1,products!$B$2:$B$5,0)),OR($B6>=INDEX(products!$C$2:$C$5,MATCH(E$1,products!$B$2:$B$5,0)),AND($B6="",INDEX(products!$I$2:$I$5,MATCH(E$1,products!$B$2:$B$5,0))=1))),1,0) -> 0 | F6: =IF(AND($D6<=90,$C6>=INDEX(products!$D$2:$D$5,MATCH(F$1,products!$B$2:$B$5,0)),OR($B6>=INDEX(products!$C$2:$C$5,MATCH(F$1,products!$B$2:$B$5,0)),AND($B6="",INDEX(products!$I$2:$I$5,MATCH(F$1,products!$B$2:$B$5,0))=1))),1,0) -> 0 | G6: =IF(AND($D6<=90,$C6>=INDEX(products!$D$2:$D$5,MATCH(G$1,products!$B$2:$B$5,0)),OR($B6>=INDEX(products!$C$2:$C$5,MATCH(G$1,products!$B$2:$B$5,0)),AND($B6="",INDEX(products!$I$2:$I$5,MATCH(G$1,products!$B$2:$B$5,0))=1))),1,0) -> 0 | H6: =IF(AND($D6<=90,$C6>=INDEX(products!$D$2:$D$5,MATCH(H$1,products!$B$2:$B$5,0)),OR($B6>=INDEX(products!$C$2:$C$5,MATCH(H$1,products!$B$2:$B$5,0)),AND($B6="",INDEX(products!$I$2:$I$5,MATCH(H$1,products!$B$2:$B$5,0))=1))),1,0) -> 1 | I6: =IFERROR(INDEX($E$1:$H$1,MATCH(1,E6:H6,0)),"No offer") -> Micro | K6: No offer | L6: =COUNTIF($I$2:$I$81,K6) -> 11
A7: 5006 | C7: 17500000 | D7: 0 | E7: =IF(AND($D7<=90,$C7>=INDEX(products!$D$2:$D$5,MATCH(E$1,products!$B$2:$B$5,0)),OR($B7>=INDEX(products!$C$2:$C$5,MATCH(E$1,products!$B$2:$B$5,0)),AND($B7="",INDEX(products!$I$2:$I$5,MATCH(E$1,products!$B$2:$B$5,0))=1))),1,0) -> 0 | F7: =IF(AND($D7<=90,$C7>=INDEX(products!$D$2:$D$5,MATCH(F$1,products!$B$2:$B$5,0)),OR($B7>=INDEX(products!$C$2:$C$5,MATCH(F$1,products!$B$2:$B$5,0)),AND($B7="",INDEX(products!$I$2:$I$5,MATCH(F$1,products!$B$2:$B$5,0))=1))),1,0) -> 0 | G7: =IF(AND($D7<=90,$C7>=INDEX(products!$D$2:$D$5,MATCH(G$1,products!$B$2:$B$5,0)),OR($B7>=INDEX(products!$C$2:$C$5,MATCH(G$1,products!$B$2:$B$5,0)),AND($B7="",INDEX(products!$I$2:$I$5,MATCH(G$1,products!$B$2:$B$5,0))=1))),1,0) -> 0 | H7: =IF(AND($D7<=90,$C7>=INDEX(products!$D$2:$D$5,MATCH(H$1,products!$B$2:$B$5,0)),OR($B7>=INDEX(products!$C$2:$C$5,MATCH(H$1,products!$B$2:$B$5,0)),AND($B7="",INDEX(products!$I$2:$I$5,MATCH(H$1,products!$B$2:$B$5,0))=1))),1,0) -> 1 | I7: =IFERROR(INDEX($E$1:$H$1,MATCH(1,E7:H7,0)),"No offer") -> Micro
A8: 5007 | B8: 779 | C8: 8500000 | D8: 9 | E8: =IF(AND($D8<=90,$C8>=INDEX(products!$D$2:$D$5,MATCH(E$1,products!$B$2:$B$5,0)),OR($B8>=INDEX(products!$C$2:$C$5,MATCH(E$1,products!$B$2:$B$5,0)),AND($B8="",INDEX(products!$I$2:$I$5,MATCH(E$1,products!$B$2:$B$5,0))=1))),1,0) -> 0 | F8: =IF(AND($D8<=90,$C8>=INDEX(products!$D$2:$D$5,MATCH(F$1,products!$B$2:$B$5,0)),OR($B8>=INDEX(products!$C$2:$C$5,MATCH(F$1,products!$B$2:$B$5,0)),AND($B8="",INDEX(products!$I$2:$I$5,MATCH(F$1,products!$B$2:$B$5,0))=1))),1,0) -> 0 | G8: =IF(AND($D8<=90,$C8>=INDEX(products!$D$2:$D$5,MATCH(G$1,products!$B$2:$B$5,0)),OR($B8>=INDEX(products!$C$2:$C$5,MATCH(G$1,products!$B$2:$B$5,0)),AND($B8="",INDEX(products!$I$2:$I$5,MATCH(G$1,products!$B$2:$B$5,0))=1))),1,0) -> 1 | H8: =IF(AND($D8<=90,$C8>=INDEX(products!$D$2:$D$5,MATCH(H$1,products!$B$2:$B$5,0)),OR($B8>=INDEX(products!$C$2:$C$5,MATCH(H$1,products!$B$2:$B$5,0)),AND($B8="",INDEX(products!$I$2:$I$5,MATCH(H$1,products!$B$2:$B$5,0))=1))),1,0) -> 1 | I8: =IFERROR(INDEX($E$1:$H$1,MATCH(1,E8:H8,0)),"No offer") -> Starter
A9: 5008 | B9: 599 | C9: 11000000 | D9: 6 | E9: =IF(AND($D9<=90,$C9>=INDEX(products!$D$2:$D$5,MATCH(E$1,products!$B$2:$B$5,0)),OR($B9>=INDEX(products!$C$2:$C$5,MATCH(E$1,products!$B$2:$B$5,0)),AND($B9="",INDEX(products!$I$2:$I$5,MATCH(E$1,products!$B$2:$B$5,0))=1))),1,0) -> 0 | F9: =IF(AND($D9<=90,$C9>=INDEX(products!$D$2:$D$5,MATCH(F$1,products!$B$2:$B$5,0)),OR($B9>=INDEX(products!$C$2:$C$5,MATCH(F$1,products!$B$2:$B$5,0)),AND($B9="",INDEX(products!$I$2:$I$5,MATCH(F$1,products!$B$2:$B$5,0))=1))),1,0) -> 0 | G9: =IF(AND($D9<=90,$C9>=INDEX(products!$D$2:$D$5,MATCH(G$1,products!$B$2:$B$5,0)),OR($B9>=INDEX(products!$C$2:$C$5,MATCH(G$1,products!$B$2:$B$5,0)),AND($B9="",INDEX(products!$I$2:$I$5,MATCH(G$1,products!$B$2:$B$5,0))=1))),1,0) -> 1 | H9: =IF(AND($D9<=90,$C9>=INDEX(products!$D$2:$D$5,MATCH(H$1,products!$B$2:$B$5,0)),OR($B9>=INDEX(products!$C$2:$C$5,MATCH(H$1,products!$B$2:$B$5,0)),AND($B9="",INDEX(products!$I$2:$I$5,MATCH(H$1,products!$B$2:$B$5,0))=1))),1,0) -> 1 | I9: =IFERROR(INDEX($E$1:$H$1,MATCH(1,E9:H9,0)),"No offer") -> Starter
A10: 5009 | B10: 468 | C10: 11000000 | D10: 325 | E10: =IF(AND($D10<=90,$C10>=INDEX(products!$D$2:$D$5,MATCH(E$1,products!$B$2:$B$5,0)),OR($B10>=INDEX(products!$C$2:$C$5,MATCH(E$1,products!$B$2:$B$5,0)),AND($B10="",INDEX(products!$I$2:$I$5,MATCH(E$1,products!$B$2:$B$5,0))=1))),1,0) -> 0 | F10: =IF(AND($D10<=90,$C10>=INDEX(products!$D$2:$D$5,MATCH(F$1,products!$B$2:$B$5,0)),OR($B10>=INDEX(products!$C$2:$C$5,MATCH(F$1,products!$B$2:$B$5,0)),AND($B10="",INDEX(products!$I$2:$I$5,MATCH(F$1,products!$B$2:$B$5,0))=1))),1,0) -> 0 | G10: =IF(AND($D10<=90,$C10>=INDEX(products!$D$2:$D$5,MATCH(G$1,products!$B$2:$B$5,0)),OR($B10>=INDEX(products!$C$2:$C$5,MATCH(G$1,products!$B$2:$B$5,0)),AND($B10="",INDEX(products!$I$2:$I$5,MATCH(G$1,products!$B$2:$B$5,0))=1))),1,0) -> 0 | H10: =IF(AND($D10<=90,$C10>=INDEX(products!$D$2:$D$5,MATCH(H$1,products!$B$2:$B$5,0)),OR($B10>=INDEX(products!$C$2:$C$5,MATCH(H$1,products!$B$2:$B$5,0)),AND($B10="",INDEX(products!$I$2:$I$5,MATCH(H$1,products!$B$2:$B$5,0))=1))),1,0) -> 0 | I10: =IFERROR(INDEX($E$1:$H$1,MATCH(1,E10:H10,0)),"No offer") -> No offer
A11: 5010 | B11: 660 | C11: 7000000 | D11: 36 | E11: =IF(AND($D11<=90,$C11>=INDEX(products!$D$2:$D$5,MATCH(E$1,products!$B$2:$B$5,0)),OR($B11>=INDEX(products!$C$2:$C$5,MATCH(E$1,products!$B$2:$B$5,0)),AND($B11="",INDEX(products!$I$2:$I$5,MATCH(E$1,products!$B$2:$B$5,0))=1))),1,0) -> 0 | F11: =IF(AND($D11<=90,$C11>=INDEX(products!$D$2:$D$5,MATCH(F$1,products!$B$2:$B$5,0)),OR($B11>=INDEX(products!$C$2:$C$5,MATCH(F$1,products!$B$2:$B$5,0)),AND($B11="",INDEX(products!$I$2:$I$5,MATCH(F$1,products!$B$2:$B$5,0))=1))),1,0) -> 0 | G11: =IF(AND($D11<=90,$C11>=INDEX(products!$D$2:$D$5,MATCH(G$1,products!$B$2:$B$5,0)),OR($B11>=INDEX(products!$C$2:$C$5,MATCH(G$1,products!$B$2:$B$5,0)),AND($B11="",INDEX(products!$I$2:$I$5,MATCH(G$1,products!$B$2:$B$5,0))=1))),1,0) -> 1 | H11: =IF(AND($D11<=90,$C11>=INDEX(products!$D$2:$D$5,MATCH(H$1,products!$B$2:$B$5,0)),OR($B11>=INDEX(products!$C$2:$C$5,MATCH(H$1,products!$B$2:$B$5,0)),AND($B11="",INDEX(products!$I$2:$I$5,MATCH(H$1,products!$B$2:$B$5,0))=1))),1,0) -> 1 | I11: =IFERROR(INDEX($E$1:$H$1,MATCH(1,E11:H11,0)),"No offer") -> Starter
A12: 5011 | C12: 6000000 | D12: 0 | E12: =IF(AND($D12<=90,$C12>=INDEX(products!$D$2:$D$5,MATCH(E$1,products!$B$2:$B$5,0)),OR($B12>=INDEX(products!$C$2:$C$5,MATCH(E$1,products!$B$2:$B$5,0)),AND($B12="",INDEX(products!$I$2:$I$5,MATCH(E$1,products!$B$2:$B$5,0))=1))),1,0) -> 0 | F12: =IF(AND($D12<=90,$C12>=INDEX(products!$D$2:$D$5,MATCH(F$1,products!$B$2:$B$5,0)),OR($B12>=INDEX(products!$C$2:$C$5,MATCH(F$1,products!$B$2:$B$5,0)),AND($B12="",INDEX(products!$I$2:$I$5,MATCH(F$1,products!$B$2:$B$5,0))=1))),1,0) -> 0 | G12: =IF(AND($D12<=90,$C12>=INDEX(products!$D$2:$D$5,MATCH(G$1,products!$B$2:$B$5,0)),OR($B12>=INDEX(products!$C$2:$C$5,MATCH(G$1,products!$B$2:$B$5,0)),AND($B12="",INDEX(products!$I$2:$I$5,MATCH(G$1,products!$B$2:$B$5,0))=1))),1,0) -> 0 | H12: =IF(AND($D12<=90,$C12>=INDEX(products!$D$2:$D$5,MATCH(H$1,products!$B$2:$B$5,0)),OR($B12>=INDEX(products!$C$2:$C$5,MATCH(H$1,products!$B$2:$B$5,0)),AND($B12="",INDEX(products!$I$2:$I$5,MATCH(H$1,products!$B$2:$B$5,0))=1))),1,0) -> 1 | I12: =IFERROR(INDEX($E$1:$H$1,MATCH(1,E12:H12,0)),"No offer") -> Micro
A13: 5012 | C13: 17500000 | D13: 0 | E13: =IF(AND($D13<=90,$C13>=INDEX(products!$D$2:$D$5,MATCH(E$1,products!$B$2:$B$5,0)),OR($B13>=INDEX(products!$C$2:$C$5,MATCH(E$1,products!$B$2:$B$5,0)),AND($B13="",INDEX(products!$I$2:$I$5,MATCH(E$1,products!$B$2:$B$5,0))=1))),1,0) -> 0 | F13: =IF(AND($D13<=90,$C13>=INDEX(products!$D$2:$D$5,MATCH(F$1,products!$B$2:$B$5,0)),OR($B13>=INDEX(products!$C$2:$C$5,MATCH(F$1,products!$B$2:$B$5,0)),AND($B13="",INDEX(products!$I$2:$I$5,MATCH(F$1,products!$B$2:$B$5,0))=1))),1,0) -> 0 | G13: =IF(AND($D13<=90,$C13>=INDEX(products!$D$2:$D$5,MATCH(G$1,products!$B$2:$B$5,0)),OR($B13>=INDEX(products!$C$2:$C$5,MATCH(G$1,products!$B$2:$B$5,0)),AND($B13="",INDEX(products!$I$2:$I$5,MATCH(G$1,products!$B$2:$B$5,0))=1))),1,0) -> 0 | H13: =IF(AND($D13<=90,$C13>=INDEX(products!$D$2:$D$5,MATCH(H$1,products!$B$2:$B$5,0)),OR($B13>=INDEX(products!$C$2:$C$5,MATCH(H$1,products!$B$2:$B$5,0)),AND($B13="",INDEX(products!$I$2:$I$5,MATCH(H$1,products!$B$2:$B$5,0))=1))),1,0) -> 1 | I13: =IFERROR(INDEX($E$1:$H$1,MATCH(1,E13:H13,0)),"No offer") -> Micro
A14: 5013 | B14: 518 | C14: 24000000 | D14: 65 | E14: =IF(AND($D14<=90,$C14>=INDEX(products!$D$2:$D$5,MATCH(E$1,products!$B$2:$B$5,0)),OR($B14>=INDEX(products!$C$2:$C$5,MATCH(E$1,products!$B$2:$B$5,0)),AND($B14="",INDEX(products!$I$2:$I$5,MATCH(E$1,products!$B$2:$B$5,0))=1))),1,0) -> 0 | F14: =IF(AND($D14<=90,$C14>=INDEX(products!$D$2:$D$5,MATCH(F$1,products!$B$2:$B$5,0)),OR($B14>=INDEX(products!$C$2:$C$5,MATCH(F$1,products!$B$2:$B$5,0)),AND($B14="",INDEX(products!$I$2:$I$5,MATCH(F$1,products!$B$2:$B$5,0))=1))),1,0) -> 0 | G14: =IF(AND($D14<=90,$C14>=INDEX(products!$D$2:$D$5,MATCH(G$1,products!$B$2:$B$5,0)),OR($B14>=INDEX(products!$C$2:$C$5,MATCH(G$1,products!$B$2:$B$5,0)),AND($B14="",INDEX(products!$I$2:$I$5,MATCH(G$1,products!$B$2:$B$5,0))=1))),1,0) -> 1 | H14: =IF(AND($D14<=90,$C14>=INDEX(products!$D$2:$D$5,MATCH(H$1,products!$B$2:$B$5,0)),OR($B14>=INDEX(products!$C$2:$C$5,MATCH(H$1,products!$B$2:$B$5,0)),AND($B14="",INDEX(products!$I$2:$I$5,MATCH(H$1,products!$B$2:$B$5,0))=1))),1,0) -> 1 | I14: =IFERROR(INDEX($E$1:$H$1,MATCH(1,E14:H14,0)),"No offer") -> Starter
A15: 5014 | C15: 12500000 | D15: 0 | E15: =IF(AND($D15<=90,$C15>=INDEX(products!$D$2:$D$5,MATCH(E$1,products!$B$2:$B$5,0)),OR($B15>=INDEX(products!$C$2:$C$5,MATCH(E$1,products!$B$2:$B$5,0)),AND($B15="",INDEX(products!$I$2:$I$5,MATCH(E$1,products!$B$2:$B$5,0))=1))),1,0) -> 0 | F15: =IF(AND($D15<=90,$C15>=INDEX(products!$D$2:$D$5,MATCH(F$1,products!$B$2:$B$5,0)),OR($B15>=INDEX(products!$C$2:$C$5,MATCH(F$1,products!$B$2:$B$5,0)),AND($B15="",INDEX(products!$I$2:$I$5,MATCH(F$1,products!$B$2:$B$5,0))=1))),1,0) -> 0 | G15: =IF(AND($D15<=90,$C15>=INDEX(products!$D$2:$D$5,MATCH(G$1,products!$B$2:$B$5,0)),OR($B15>=INDEX(products!$C$2:$C$5,MATCH(G$1,products!$B$2:$B$5,0)),AND($B15="",INDEX(products!$I$2:$I$5,MATCH(G$1,products!$B$2:$B$5,0))=1))),1,0) -> 0 | H15: =IF(AND($D15<=90,$C15>=INDEX(products!$D$2:$D$5,MATCH(H$1,products!$B$2:$B$5,0)),OR($B15>=INDEX(products!$C$2:$C$5,MATCH(H$1,products!$B$2:$B$5,0)),AND($B15="",INDEX(products!$I$2:$I$5,MATCH(H$1,products!$B$2:$B$5,0))=1))),1,0) -> 1 | I15: =IFERROR(INDEX($E$1:$H$1,MATCH(1,E15:H15,0)),"No offer") -> Micro
A16: 5015 | B16: 442 | C16: 9500000 | D16: 183 | E16: =IF(AND($D16<=90,$C16>=INDEX(products!$D$2:$D$5,MATCH(E$1,products!$B$2:$B$5,0)),OR($B16>=INDEX(products!$C$2:$C$5,MATCH(E$1,products!$B$2:$B$5,0)),AND($B16="",INDEX(products!$I$2:$I$5,MATCH(E$1,products!$B$2:$B$5,0))=1))),1,0) -> 0 | F16: =IF(AND($D16<=90,$C16>=INDEX(products!$D$2:$D$5,MATCH(F$1,products!$B$2:$B$5,0)),OR($B16>=INDEX(products!$C$2:$C$5,MATCH(F$1,products!$B$2:$B$5,0)),AND($B16="",INDEX(products!$I$2:$I$5,MATCH(F$1,products!$B$2:$B$5,0))=1))),1,0) -> 0 | G16: =IF(AND($D16<=90,$C16>=INDEX(products!$D$2:$D$5,MATCH(G$1,products!$B$2:$B$5,0)),OR($B16>=INDEX(products!$C$2:$C$5,MATCH(G$1,products!$B$2:$B$5,0)),AND($B16="",INDEX(products!$I$2:$I$5,MATCH(G$1,products!$B$2:$B$5,0))=1))),1,0) -> 0 | H16: =IF(AND($D16<=90,$C16>=INDEX(products!$D$2:$D$5,MATCH(H$1,products!$B$2:$B$5,0)),OR($B16>=INDEX(products!$C$2:$C$5,MATCH(H$1,products!$B$2:$B$5,0)),AND($B16="",INDEX(products!$I$2:$I$5,MATCH(H$1,products!$B$2:$B$5,0))=1))),1,0) -> 0 | I16: =IFERROR(INDEX($E$1:$H$1,MATCH(1,E16:H16,0)),"No offer") -> No offer
A17: 5016 | C17: 26000000 | D17: 0 | E17: =IF(AND($D17<=90,$C17>=INDEX(products!$D$2:$D$5,MATCH(E$1,products!$B$2:$B$5,0)),OR($B17>=INDEX(products!$C$2:$C$5,MATCH(E$1,products!$B$2:$B$5,0)),AND($B17="",INDEX(products!$I$2:$I$5,MATCH(E$1,products!$B$2:$B$5,0))=1))),1,0) -> 0 | F17: =IF(AND($D17<=90,$C17>=INDEX(products!$D$2:$D$5,MATCH(F$1,products!$B$2:$B$5,0)),OR($B17>=INDEX(products!$C$2:$C$5,MATCH(F$1,products!$B$2:$B$5,0)),AND($B17="",INDEX(products!$I$2:$I$5,MATCH(F$1,products!$B$2:$B$5,0))=1))),1,0) -> 0 | G17: =IF(AND($D17<=90,$C17>=INDEX(products!$D$2:$D$5,MATCH(G$1,products!$B$2:$B$5,0)),OR($B17>=INDEX(products!$C$2:$C$5,MATCH(G$1,products!$B$2:$B$5,0)),AND($B17="",INDEX(products!$I$2:$I$5,MATCH(G$1,products!$B$2:$B$5,0))=1))),1,0) -> 0 | H17: =IF(AND($D17<=90,$C17>=INDEX(products!$D$2:$D$5,MATCH(H$1,products!$B$2:$B$5,0)),OR($B17>=INDEX(products!$C$2:$C$5,MATCH(H$1,products!$B$2:$B$5,0)),AND($B17="",INDEX(products!$I$2:$I$5,MATCH(H$1,products!$B$2:$B$5,0))=1))),1,0) -> 1 | I17: =IFERROR(INDEX($E$1:$H$1,MATCH(1,E17:H17,0)),"No offer") -> Micro
A18: 5017 | C18: 6000000 | D18: 0 | E18: =IF(AND($D18<=90,$C18>=INDEX(products!$D$2:$D$5,MATCH(E$1,products!$B$2:$B$5,0)),OR($B18>=INDEX(products!$C$2:$C$5,MATCH(E$1,products!$B$2:$B$5,0)),AND($B18="",INDEX(products!$I$2:$I$5,MATCH(E$1,products!$B$2:$B$5,0))=1))),1,0) -> 0 | F18: =IF(AND($D18<=90,$C18>=INDEX(products!$D$2:$D$5,MATCH(F$1,products!$B$2:$B$5,0)),OR($B18>=INDEX(products!$C$2:$C$5,MATCH(F$1,products!$B$2:$B$5,0)),AND($B18="",INDEX(products!$I$2:$I$5,MATCH(F$1,products!$B$2:$B$5,0))=1))),1,0) -> 0 | G18: =IF(AND($D18<=90,$C18>=INDEX(products!$D$2:$D$5,MATCH(G$1,products!$B$2:$B$5,0)),OR($B18>=INDEX(products!$C$2:$C$5,MATCH(G$1,products!$B$2:$B$5,0)),AND($B18="",INDEX(products!$I$2:$I$5,MATCH(G$1,products!$B$2:$B$5,0))=1))),1,0) -> 0 | H18: =IF(AND($D18<=90,$C18>=INDEX(products!$D$2:$D$5,MATCH(H$1,products!$B$2:$B$5,0)),OR($B18>=INDEX(products!$C$2:$C$5,MATCH(H$1,products!$B$2:$B$5,0)),AND($B18="",INDEX(products!$I$2:$I$5,MATCH(H$1,products!$B$2:$B$5,0))=1))),1,0) -> 1 | I18: =IFERROR(INDEX($E$1:$H$1,MATCH(1,E18:H18,0)),"No offer") -> Micro
A19: 5018 | B19: 631 | C19: 14500000 | D19: 6 | E19: =IF(AND($D19<=90,$C19>=INDEX(products!$D$2:$D$5,MATCH(E$1,products!$B$2:$B$5,0)),OR($B19>=INDEX(products!$C$2:$C$5,MATCH(E$1,products!$B$2:$B$5,0)),AND($B19="",INDEX(products!$I$2:$I$5,MATCH(E$1,products!$B$2:$B$5,0))=1))),1,0) -> 0 | F19: =IF(AND($D19<=90,$C19>=INDEX(products!$D$2:$D$5,MATCH(F$1,products!$B$2:$B$5,0)),OR($B19>=INDEX(products!$C$2:$C$5,MATCH(F$1,products!$B$2:$B$5,0)),AND($B19="",INDEX(products!$I$2:$I$5,MATCH(F$1,products!$B$2:$B$5,0))=1))),1,0) -> 1 | G19: =IF(AND($D19<=90,$C19>=INDEX(products!$D$2:$D$5,MATCH(G$1,products!$B$2:$B$5,0)),OR($B19>=INDEX(products!$C$2:$C$5,MATCH(G$1,products!$B$2:$B$5,0)),AND($B19="",INDEX(products!$I$2:$I$5,MATCH(G$1,products!$B$2:$B$5,0))=1))),1,0) -> 1 | H19: =IF(AND($D19<=90,$C19>=INDEX(products!$D$2:$D$5,MATCH(H$1,products!$B$2:$B$5,0)),OR($B19>=INDEX(products!$C$2:$C$5,MATCH(H$1,products!$B$2:$B$5,0)),AND($B19="",INDEX(products!$I$2:$I$5,MATCH(H$1,products!$B$2:$B$5,0))=1))),1,0) -> 1 | I19: =IFERROR(INDEX($E$1:$H$1,MATCH(1,E19:H19,0)),"No offer") -> Standard
A20: 5019 | B20: 699 | C20: 21000000 | D20: 8 | E20: =IF(AND($D20<=90,$C20>=INDEX(products!$D$2:$D$5,MATCH(E$1,products!$B$2:$B$5,0)),OR($B20>=INDEX(products!$C$2:$C$5,MATCH(E$1,products!$B$2:$B$5,0)),AND($B20="",INDEX(products!$I$2:$I$5,MATCH(E$1,products!$B$2:$B$5,0))=1))),1,0) -> 0 | F20: =IF(AND($D20<=90,$C20>=INDEX(products!$D$2:$D$5,MATCH(F$1,products!$B$2:$B$5,0)),OR($B20>=INDEX(products!$C$2:$C$5,MATCH(F$1,products!$B$2:$B$5,0)),AND($B20="",INDEX(products!$I$2:$I$5,MATCH(F$1,products!$B$2:$B$5,0))=1))),1,0) -> 1 | G20: =IF(AND($D20<=90,$C20>=INDEX(products!$D$2:$D$5,MATCH(G$1,products!$B$2:$B$5,0)),OR($B20>=INDEX(products!$C$2:$C$5,MATCH(G$1,products!$B$2:$B$5,0)),AND($B20="",INDEX(products!$I$2:$I$5,MATCH(G$1,products!$B$2:$B$5,0))=1))),1,0) -> 1 | H20: =IF(AND($D20<=90,$C20>=INDEX(products!$D$2:$D$5,MATCH(H$1,products!$B$2:$B$5,0)),OR($B20>=INDEX(products!$C$2:$C$5,MATCH(H$1,products!$B$2:$B$5,0)),AND($B20="",INDEX(products!$I$2:$I$5,MATCH(H$1,products!$B$2:$B$5,0))=1))),1,0) -> 1 | I20: =IFERROR(INDEX($E$1:$H$1,MATCH(1,E20:H20,0)),"No offer") -> Standard
A21: 5020 | C21: 26000000 | D21: 0 | E21: =IF(AND($D21<=90,$C21>=INDEX(products!$D$2:$D$5,MATCH(E$1,products!$B$2:$B$5,0)),OR($B21>=INDEX(products!$C$2:$C$5,MATCH(E$1,products!$B$2:$B$5,0)),AND($B21="",INDEX(products!$I$2:$I$5,MATCH(E$1,products!$B$2:$B$5,0))=1))),1,0) -> 0 | F21: =IF(AND($D21<=90,$C21>=INDEX(products!$D$2:$D$5,MATCH(F$1,products!$B$2:$B$5,0)),OR($B21>=INDEX(products!$C$2:$C$5,MATCH(F$1,products!$B$2:$B$5,0)),AND($B21="",INDEX(products!$I$2:$I$5,MATCH(F$1,products!$B$2:$B$5,0))=1))),1,0) -> 0 | G21: =IF(AND($D21<=90,$C21>=INDEX(products!$D$2:$D$5,MATCH(G$1,products!$B$2:$B$5,0)),OR($B21>=INDEX(products!$C$2:$C$5,MATCH(G$1,products!$B$2:$B$5,0)),AND($B21="",INDEX(products!$I$2:$I$5,MATCH(G$1,products!$B$2:$B$5,0))=1))),1,0) -> 0 | H21: =IF(AND($D21<=90,$C21>=INDEX(products!$D$2:$D$5,MATCH(H$1,products!$B$2:$B$5,0)),OR($B21>=INDEX(products!$C$2:$C$5,MATCH(H$1,products!$B$2:$B$5,0)),AND($B21="",INDEX(products!$I$2:$I$5,MATCH(H$1,products!$B$2:$B$5,0))=1))),1,0) -> 1 | I21: =IFERROR(INDEX($E$1:$H$1,MATCH(1,E21:H21,0)),"No offer") -> Micro
A22: 5021 | B22: 577 | C22: 8500000 | D22: 77 | E22: =IF(AND($D22<=90,$C22>=INDEX(products!$D$2:$D$5,MATCH(E$1,products!$B$2:$B$5,0)),OR($B22>=INDEX(products!$C$2:$C$5,MATCH(E$1,products!$B$2:$B$5,0)),AND($B22="",INDEX(products!$I$2:$I$5,MATCH(E$1,products!$B$2:$B$5,0))=1))),1,0) -> 0 | F22: =IF(AND($D22<=90,$C22>=INDEX(products!$D$2:$D$5,MATCH(F$1,products!$B$2:$B$5,0)),OR($B22>=INDEX(products!$C$2:$C$5,MATCH(F$1,products!$B$2:$B$5,0)),AND($B22="",INDEX(products!$I$2:$I$5,MATCH(F$1,products!$B$2:$B$5,0))=1))),1,0) -> 0 | G22: =IF(AND($D22<=90,$C22>=INDEX(products!$D$2:$D$5,MATCH(G$1,products!$B$2:$B$5,0)),OR($B22>=INDEX(products!$C$2:$C$5,MATCH(G$1,products!$B$2:$B$5,0)),AND($B22="",INDEX(products!$I$2:$I$5,MATCH(G$1,products!$B$2:$B$5,0))=1))),1,0) -> 1 | H22: =IF(AND($D22<=90,$C22>=INDEX(products!$D$2:$D$5,MATCH(H$1,products!$B$2:$B$5,0)),OR($B22>=INDEX(products!$C$2:$C$5,MATCH(H$1,products!$B$2:$B$5,0)),AND($B22="",INDEX(products!$I$2:$I$5,MATCH(H$1,products!$B$2:$B$5,0))=1))),1,0) -> 1 | I22: =IFERROR(INDEX($E$1:$H$1,MATCH(1,E22:H22,0)),"No offer") -> Starter
A23: 5022 | B23: 564 | C23: 9500000 | D23: 9 | E23: =IF(AND($D23<=90,$C23>=INDEX(products!$D$2:$D$5,MATCH(E$1,products!$B$2:$B$5,0)),OR($B23>=INDEX(products!$C$2:$C$5,MATCH(E$1,products!$B$2:$B$5,0)),AND($B23="",INDEX(products!$I$2:$I$5,MATCH(E$1,products!$B$2:$B$5,0))=1))),1,0) -> 0 | F23: =IF(AND($D23<=90,$C23>=INDEX(products!$D$2:$D$5,MATCH(F$1,products!$B$2:$B$5,0)),OR($B23>=INDEX(products!$C$2:$C$5,MATCH(F$1,products!$B$2:$B$5,0)),AND($B23="",INDEX(products!$I$2:$I$5,MATCH(F$1,products!$B$2:$B$5,0))=1))),1,0) -> 0 | G23: =IF(AND($D23<=90,$C23>=INDEX(products!$D$2:$D$5,MATCH(G$1,products!$B$2:$B$5,0)),OR($B23>=INDEX(products!$C$2:$C$5,MATCH(G$1,products!$B$2:$B$5,0)),AND($B23="",INDEX(products!$I$2:$I$5,MATCH(G$1,products!$B$2:$B$5,0))=1))),1,0) -> 1 | H23: =IF(AND($D23<=90,$C23>=INDEX(products!$D$2:$D$5,MATCH(H$1,products!$B$2:$B$5,0)),OR($B23>=INDEX(products!$C$2:$C$5,MATCH(H$1,products!$B$2:$B$5,0)),AND($B23="",INDEX(products!$I$2:$I$5,MATCH(H$1,products!$B$2:$B$5,0))=1))),1,0) -> 1 | I23: =IFERROR(INDEX($E$1:$H$1,MATCH(1,E23:H23,0)),"No offer") -> Starter
A24: 5023 | C24: 6000000 | D24: 0 | E24: =IF(AND($D24<=90,$C24>=INDEX(products!$D$2:$D$5,MATCH(E$1,products!$B$2:$B$5,0)),OR($B24>=INDEX(products!$C$2:$C$5,MATCH(E$1,products!$B$2:$B$5,0)),AND($B24="",INDEX(products!$I$2:$I$5,MATCH(E$1,products!$B$2:$B$5,0))=1))),1,0) -> 0 | F24: =IF(AND($D24<=90,$C24>=INDEX(products!$D$2:$D$5,MATCH(F$1,products!$B$2:$B$5,0)),OR($B24>=INDEX(products!$C$2:$C$5,MATCH(F$1,products!$B$2:$B$5,0)),AND($B24="",INDEX(products!$I$2:$I$5,MATCH(F$1,products!$B$2:$B$5,0))=1))),1,0) -> 0 | G24: =IF(AND($D24<=90,$C24>=INDEX(products!$D$2:$D$5,MATCH(G$1,products!$B$2:$B$5,0)),OR($B24>=INDEX(products!$C$2:$C$5,MATCH(G$1,products!$B$2:$B$5,0)),AND($B24="",INDEX(products!$I$2:$I$5,MATCH(G$1,products!$B$2:$B$5,0))=1))),1,0) -> 0 | H24: =IF(AND($D24<=90,$C24>=INDEX(products!$D$2:$D$5,MATCH(H$1,products!$B$2:$B$5,0)),OR($B24>=INDEX(products!$C$2:$C$5,MATCH(H$1,products!$B$2:$B$5,0)),AND($B24="",INDEX(products!$I$2:$I$5,MATCH(H$1,products!$B$2:$B$5,0))=1))),1,0) -> 1 | I24: =IFERROR(INDEX($E$1:$H$1,MATCH(1,E24:H24,0)),"No offer") -> Micro
A25: 5024 | B25: 760 | C25: 45000000 | D25: 3 | E25: =IF(AND($D25<=90,$C25>=INDEX(products!$D$2:$D$5,MATCH(E$1,products!$B$2:$B$5,0)),OR($B25>=INDEX(products!$C$2:$C$5,MATCH(E$1,products!$B$2:$B$5,0)),AND($B25="",INDEX(products!$I$2:$I$5,MATCH(E$1,products!$B$2:$B$5,0))=1))),1,0) -> 1 | F25: =IF(AND($D25<=90,$C25>=INDEX(products!$D$2:$D$5,MATCH(F$1,products!$B$2:$B$5,0)),OR($B25>=INDEX(products!$C$2:$C$5,MATCH(F$1,products!$B$2:$B$5,0)),AND($B25="",INDEX(products!$I$2:$I$5,MATCH(F$1,products!$B$2:$B$5,0))=1))),1,0) -> 1 | G25: =IF(AND($D25<=90,$C25>=INDEX(products!$D$2:$D$5,MATCH(G$1,products!$B$2:$B$5,0)),OR($B25>=INDEX(products!$C$2:$C$5,MATCH(G$1,products!$B$2:$B$5,0)),AND($B25="",INDEX(products!$I$2:$I$5,MATCH(G$1,products!$B$2:$B$5,0))=1))),1,0) -> 1 | H25: =IF(AND($D25<=90,$C25>=INDEX(products!$D$2:$D$5,MATCH(H$1,products!$B$2:$B$5,0)),OR($B25>=INDEX(products!$C$2:$C$5,MATCH(H$1,products!$B$2:$B$5,0)),AND($B25="",INDEX(products!$I$2:$I$5,MATCH(H$1,products!$B$2:$B$5,0))=1))),1,0) -> 1 | I25: =IFERROR(INDEX($E$1:$H$1,MATCH(1,E25:H25,0)),"No offer") -> Prime
A26: 5025 | B26: 563 | C26: 13000000 | D26: 68 | E26: =IF(AND($D26<=90,$C26>=INDEX(products!$D$2:$D$5,MATCH(E$1,products!$B$2:$B$5,0)),OR($B26>=INDEX(products!$C$2:$C$5,MATCH(E$1,products!$B$2:$B$5,0)),AND($B26="",INDEX(products!$I$2:$I$5,MATCH(E$1,products!$B$2:$B$5,0))=1))),1,0) -> 0 | F26: =IF(AND($D26<=90,$C26>=INDEX(products!$D$2:$D$5,MATCH(F$1,products!$B$2:$B$5,0)),OR($B26>=INDEX(products!$C$2:$C$5,MATCH(F$1,products!$B$2:$B$5,0)),AND($B26="",INDEX(products!$I$2:$I$5,MATCH(F$1,products!$B$2:$B$5,0))=1))),1,0) -> 0 | G26: =IF(AND($D26<=90,$C26>=INDEX(products!$D$2:$D$5,MATCH(G$1,products!$B$2:$B$5,0)),OR($B26>=INDEX(products!$C$2:$C$5,MATCH(G$1,products!$B$2:$B$5,0)),AND($B26="",INDEX(products!$I$2:$I$5,MATCH(G$1,products!$B$2:$B$5,0))=1))),1,0) -> 1 | H26: =IF(AND($D26<=90,$C26>=INDEX(products!$D$2:$D$5,MATCH(H$1,products!$B$2:$B$5,0)),OR($B26>=INDEX(products!$C$2:$C$5,MATCH(H$1,products!$B$2:$B$5,0)),AND($B26="",INDEX(products!$I$2:$I$5,MATCH(H$1,products!$B$2:$B$5,0))=1))),1,0) -> 1 | I26: =IFERROR(INDEX($E$1:$H$1,MATCH(1,E26:H26,0)),"No offer") -> Starter
A27: 5026 | B27: 642 | C27: 4500000 | D27: 6 | E27: =IF(AND($D27<=90,$C27>=INDEX(products!$D$2:$D$5,MATCH(E$1,products!$B$2:$B$5,0)),OR($B27>=INDEX(products!$C$2:$C$5,MATCH(E$1,products!$B$2:$B$5,0)),AND($B27="",INDEX(products!$I$2:$I$5,MATCH(E$1,products!$B$2:$B$5,0))=1))),1,0) -> 0 | F27: =IF(AND($D27<=90,$C27>=INDEX(products!$D$2:$D$5,MATCH(F$1,products!$B$2:$B$5,0)),OR($B27>=INDEX(products!$C$2:$C$5,MATCH(F$1,products!$B$2:$B$5,0)),AND($B27="",INDEX(products!$I$2:$I$5,MATCH(F$1,products!$B$2:$B$5,0))=1))),1,0) -> 0 | G27: =IF(AND($D27<=90,$C27>=INDEX(products!$D$2:$D$5,MATCH(G$1,products!$B$2:$B$5,0)),OR($B27>=INDEX(products!$C$2:$C$5,MATCH(G$1,products!$B$2:$B$5,0)),AND($B27="",INDEX(products!$I$2:$I$5,MATCH(G$1,products!$B$2:$B$5,0))=1))),1,0) -> 0 | H27: =IF(AND($D27<=90,$C27>=INDEX(products!$D$2:$D$5,MATCH(H$1,products!$B$2:$B$5,0)),OR($B27>=INDEX(products!$C$2:$C$5,MATCH(H$1,products!$B$2:$B$5,0)),AND($B27="",INDEX(products!$I$2:$I$5,MATCH(H$1,products!$B$2:$B$5,0))=1))),1,0) -> 0 | I27: =IFERROR(INDEX($E$1:$H$1,MATCH(1,E27:H27,0)),"No offer") -> No offer
A28: 5027 | C28: 10000000 | D28: 0 | E28: =IF(AND($D28<=90,$C28>=INDEX(products!$D$2:$D$5,MATCH(E$1,products!$B$2:$B$5,0)),OR($B28>=INDEX(products!$C$2:$C$5,MATCH(E$1,products!$B$2:$B$5,0)),AND($B28="",INDEX(products!$I$2:$I$5,MATCH(E$1,products!$B$2:$B$5,0))=1))),1,0) -> 0 | F28: =IF(AND($D28<=90,$C28>=INDEX(products!$D$2:$D$5,MATCH(F$1,products!$B$2:$B$5,0)),OR($B28>=INDEX(products!$C$2:$C$5,MATCH(F$1,products!$B$2:$B$5,0)),AND($B28="",INDEX(products!$I$2:$I$5,MATCH(F$1,products!$B$2:$B$5,0))=1))),1,0) -> 0 | G28: =IF(AND($D28<=90,$C28>=INDEX(products!$D$2:$D$5,MATCH(G$1,products!$B$2:$B$5,0)),OR($B28>=INDEX(products!$C$2:$C$5,MATCH(G$1,products!$B$2:$B$5,0)),AND($B28="",INDEX(products!$I$2:$I$5,MATCH(G$1,products!$B$2:$B$5,0))=1))),1,0) -> 0 | H28: =IF(AND($D28<=90,$C28>=INDEX(products!$D$2:$D$5,MATCH(H$1,products!$B$2:$B$5,0)),OR($B28>=INDEX(products!$C$2:$C$5,MATCH(H$1,products!$B$2:$B$5,0)),AND($B28="",INDEX(products!$I$2:$I$5,MATCH(H$1,products!$B$2:$B$5,0))=1))),1,0) -> 1 | I28: =IFERROR(INDEX($E$1:$H$1,MATCH(1,E28:H28,0)),"No offer") -> Micro
A29: 5028 | B29: 687 | C29: 23000000 | D29: 4 | E29: =IF(AND($D29<=90,$C29>=INDEX(products!$D$2:$D$5,MATCH(E$1,products!$B$2:$B$5,0)),OR($B29>=INDEX(products!$C$2:$C$5,MATCH(E$1,products!$B$2:$B$5,0)),AND($B29="",INDEX(products!$I$2:$I$5,MATCH(E$1,products!$B$2:$B$5,0))=1))),1,0) -> 0 | F29: =IF(AND($D29<=90,$C29>=INDEX(products!$D$2:$D$5,MATCH(F$1,products!$B$2:$B$5,0)),OR($B29>=INDEX(products!$C$2:$C$5,MATCH(F$1,products!$B$2:$B$5,0)),AND($B29="",INDEX(products!$I$2:$I$5,MATCH(F$1,products!$B$2:$B$5,0))=1))),1,0) -> 1 | G29: =IF(AND($D29<=90,$C29>=INDEX(products!$D$2:$D$5,MATCH(G$1,products!$B$2:$B$5,0)),OR($B29>=INDEX(products!$C$2:$C$5,MATCH(G$1,products!$B$2:$B$5,0)),AND($B29="",INDEX(products!$I$2:$I$5,MATCH(G$1,products!$B$2:$B$5,0))=1))),1,0) -> 1 | H29: =IF(AND($D29<=90,$C29>=INDEX(products!$D$2:$D$5,MATCH(H$1,products!$B$2:$B$5,0)),OR($B29>=INDEX(products!$C$2:$C$5,MATCH(H$1,products!$B$2:$B$5,0)),AND($B29="",INDEX(products!$I$2:$I$5,MATCH(H$1,products!$B$2:$B$5,0))=1))),1,0) -> 1 | I29: =IFERROR(INDEX($E$1:$H$1,MATCH(1,E29:H29,0)),"No offer") -> Standard
A30: 5029 | C30: 7500000 | D30: 0 | E30: =IF(AND($D30<=90,$C30>=INDEX(products!$D$2:$D$5,MATCH(E$1,products!$B$2:$B$5,0)),OR($B30>=INDEX(products!$C$2:$C$5,MATCH(E$1,products!$B$2:$B$5,0)),AND($B30="",INDEX(products!$I$2:$I$5,MATCH(E$1,products!$B$2:$B$5,0))=1))),1,0) -> 0 | F30: =IF(AND($D30<=90,$C30>=INDEX(products!$D$2:$D$5,MATCH(F$1,products!$B$2:$B$5,0)),OR($B30>=INDEX(products!$C$2:$C$5,MATCH(F$1,products!$B$2:$B$5,0)),AND($B30="",INDEX(products!$I$2:$I$5,MATCH(F$1,products!$B$2:$B$5,0))=1))),1,0) -> 0 | G30: =IF(AND($D30<=90,$C30>=INDEX(products!$D$2:$D$5,MATCH(G$1,products!$B$2:$B$5,0)),OR($B30>=INDEX(products!$C$2:$C$5,MATCH(G$1,products!$B$2:$B$5,0)),AND($B30="",INDEX(products!$I$2:$I$5,MATCH(G$1,products!$B$2:$B$5,0))=1))),1,0) -> 0 | H30: =IF(AND($D30<=90,$C30>=INDEX(products!$D$2:$D$5,MATCH(H$1,products!$B$2:$B$5,0)),OR($B30>=INDEX(products!$C$2:$C$5,MATCH(H$1,products!$B$2:$B$5,0)),AND($B30="",INDEX(products!$I$2:$I$5,MATCH(H$1,products!$B$2:$B$5,0))=1))),1,0) -> 1 | I30: =IFERROR(INDEX($E$1:$H$1,MATCH(1,E30:H30,0)),"No offer") -> Micro
A31: 5030 | B31: 628 | C31: 15500000 | D31: 72 | E31: =IF(AND($D31<=90,$C31>=INDEX(products!$D$2:$D$5,MATCH(E$1,products!$B$2:$B$5,0)),OR($B31>=INDEX(products!$C$2:$C$5,MATCH(E$1,products!$B$2:$B$5,0)),AND($B31="",INDEX(products!$I$2:$I$5,MATCH(E$1,products!$B$2:$B$5,0))=1))),1,0) -> 0 | F31: =IF(AND($D31<=90,$C31>=INDEX(products!$D$2:$D$5,MATCH(F$1,products!$B$2:$B$5,0)),OR($B31>=INDEX(products!$C$2:$C$5,MATCH(F$1,products!$B$2:$B$5,0)),AND($B31="",INDEX(products!$I$2:$I$5,MATCH(F$1,products!$B$2:$B$5,0))=1))),1,0) -> 1 | G31: =IF(AND($D31<=90,$C31>=INDEX(products!$D$2:$D$5,MATCH(G$1,products!$B$2:$B$5,0)),OR($B31>=INDEX(products!$C$2:$C$5,MATCH(G$1,products!$B$2:$B$5,0)),AND($B31="",INDEX(products!$I$2:$I$5,MATCH(G$1,products!$B$2:$B$5,0))=1))),1,0) -> 1 | H31: =IF(AND($D31<=90,$C31>=INDEX(products!$D$2:$D$5,MATCH(H$1,products!$B$2:$B$5,0)),OR($B31>=INDEX(products!$C$2:$C$5,MATCH(H$1,products!$B$2:$B$5,0)),AND($B31="",INDEX(products!$I$2:$I$5,MATCH(H$1,products!$B$2:$B$5,0))=1))),1,0) -> 1 | I31: =IFERROR(INDEX($E$1:$H$1,MATCH(1,E31:H31,0)),"No offer") -> Standard
A32: 5031 | B32: 723 | C32: 8500000 | D32: 8 | E32: =IF(AND($D32<=90,$C32>=INDEX(products!$D$2:$D$5,MATCH(E$1,products!$B$2:$B$5,0)),OR($B32>=INDEX(products!$C$2:$C$5,MATCH(E$1,products!$B$2:$B$5,0)),AND($B32="",INDEX(products!$I$2:$I$5,MATCH(E$1,products!$B$2:$B$5,0))=1))),1,0) -> 0 | F32: =IF(AND($D32<=90,$C32>=INDEX(products!$D$2:$D$5,MATCH(F$1,products!$B$2:$B$5,0)),OR($B32>=INDEX(products!$C$2:$C$5,MATCH(F$1,products!$B$2:$B$5,0)),AND($B32="",INDEX(products!$I$2:$I$5,MATCH(F$1,products!$B$2:$B$5,0))=1))),1,0) -> 0 | G32: =IF(AND($D32<=90,$C32>=INDEX(products!$D$2:$D$5,MATCH(G$1,products!$B$2:$B$5,0)),OR($B32>=INDEX(products!$C$2:$C$5,MATCH(G$1,products!$B$2:$B$5,0)),AND($B32="",INDEX(products!$I$2:$I$5,MATCH(G$1,products!$B$2:$B$5,0))=1))),1,0) -> 1 | H32: =IF(AND($D32<=90,$C32>=INDEX(products!$D$2:$D$5,MATCH(H$1,products!$B$2:$B$5,0)),OR($B32>=INDEX(products!$C$2:$C$5,MATCH(H$1,products!$B$2:$B$5,0)),AND($B32="",INDEX(products!$I$2:$I$5,MATCH(H$1,products!$B$2:$B$5,0))=1))),1,0) -> 1 | I32: =IFERROR(INDEX($E$1:$H$1,MATCH(1,E32:H32,0)),"No offer") -> Starter
A33: 5032 | B33: 842 | C33: 4500000 | D33: 8 | E33: =IF(AND($D33<=90,$C33>=INDEX(products!$D$2:$D$5,MATCH(E$1,products!$B$2:$B$5,0)),OR($B33>=INDEX(products!$C$2:$C$5,MATCH(E$1,products!$B$2:$B$5,0)),AND($B33="",INDEX(products!$I$2:$I$5,MATCH(E$1,products!$B$2:$B$5,0))=1))),1,0) -> 0 | F33: =IF(AND($D33<=90,$C33>=INDEX(products!$D$2:$D$5,MATCH(F$1,products!$B$2:$B$5,0)),OR($B33>=INDEX(products!$C$2:$C$5,MATCH(F$1,products!$B$2:$B$5,0)),AND($B33="",INDEX(products!$I$2:$I$5,MATCH(F$1,products!$B$2:$B$5,0))=1))),1,0) -> 0 | G33: =IF(AND($D33<=90,$C33>=INDEX(products!$D$2:$D$5,MATCH(G$1,products!$B$2:$B$5,0)),OR($B33>=INDEX(products!$C$2:$C$5,MATCH(G$1,products!$B$2:$B$5,0)),AND($B33="",INDEX(products!$I$2:$I$5,MATCH(G$1,products!$B$2:$B$5,0))=1))),1,0) -> 0 | H33: =IF(AND($D33<=90,$C33>=INDEX(products!$D$2:$D$5,MATCH(H$1,products!$B$2:$B$5,0)),OR($B33>=INDEX(products!$C$2:$C$5,MATCH(H$1,products!$B$2:$B$5,0)),AND($B33="",INDEX(products!$I$2:$I$5,MATCH(H$1,products!$B$2:$B$5,0))=1))),1,0) -> 0 | I33: =IFERROR(INDEX($E$1:$H$1,MATCH(1,E33:H33,0)),"No offer") -> No offer
A34: 5033 | B34: 413 | C34: 18500000 | D34: 339 | E34: =IF(AND($D34<=90,$C34>=INDEX(products!$D$2:$D$5,MATCH(E$1,products!$B$2:$B$5,0)),OR($B34>=INDEX(products!$C$2:$C$5,MATCH(E$1,products!$B$2:$B$5,0)),AND($B34="",INDEX(products!$I$2:$I$5,MATCH(E$1,products!$B$2:$B$5,0))=1))),1,0) -> 0 | F34: =IF(AND($D34<=90,$C34>=INDEX(products!$D$2:$D$5,MATCH(F$1,products!$B$2:$B$5,0)),OR($B34>=INDEX(products!$C$2:$C$5,MATCH(F$1,products!$B$2:$B$5,0)),AND($B34="",INDEX(products!$I$2:$I$5,MATCH(F$1,products!$B$2:$B$5,0))=1))),1,0) -> 0 | G34: =IF(AND($D34<=90,$C34>=INDEX(products!$D$2:$D$5,MATCH(G$1,products!$B$2:$B$5,0)),OR($B34>=INDEX(products!$C$2:$C$5,MATCH(G$1,products!$B$2:$B$5,0)),AND($B34="",INDEX(products!$I$2:$I$5,MATCH(G$1,products!$B$2:$B$5,0))=1))),1,0) -> 0 | H34: =IF(AND($D34<=90,$C34>=INDEX(products!$D$2:$D$5,MATCH(H$1,products!$B$2:$B$5,0)),OR($B34>=INDEX(products!$C$2:$C$5,MATCH(H$1,products!$B$2:$B$5,0)),AND($B34="",INDEX(products!$I$2:$I$5,MATCH(H$1,products!$B$2:$B$5,0))=1))),1,0) -> 0 | I34: =IFERROR(INDEX($E$1:$H$1,MATCH(1,E34:H34,0)),"No offer") -> No offer
A35: 5034 | B35: 840 | C35: 14500000 | D35: 7 | E35: =IF(AND($D35<=90,$C35>=INDEX(products!$D$2:$D$5,MATCH(E$1,products!$B$2:$B$5,0)),OR($B35>=INDEX(products!$C$2:$C$5,MATCH(E$1,products!$B$2:$B$5,0)),AND($B35="",INDEX(products!$I$2:$I$5,MATCH(E$1,products!$B$2:$B$5,0))=1))),1,0) -> 0 | F35: =IF(AND($D35<=90,$C35>=INDEX(products!$D$2:$D$5,MATCH(F$1,products!$B$2:$B$5,0)),OR($B35>=INDEX(products!$C$2:$C$5,MATCH(F$1,products!$B$2:$B$5,0)),AND($B35="",INDEX(products!$I$2:$I$5,MATCH(F$1,products!$B$2:$B$5,0))=1))),1,0) -> 1 | G35: =IF(AND($D35<=90,$C35>=INDEX(products!$D$2:$D$5,MATCH(G$1,products!$B$2:$B$5,0)),OR($B35>=INDEX(products!$C$2:$C$5,MATCH(G$1,products!$B$2:$B$5,0)),AND($B35="",INDEX(products!$I$2:$I$5,MATCH(G$1,products!$B$2:$B$5,0))=1))),1,0) -> 1 | H35: =IF(AND($D35<=90,$C35>=INDEX(products!$D$2:$D$5,MATCH(H$1,products!$B$2:$B$5,0)),OR($B35>=INDEX(products!$C$2:$C$5,MATCH(H$1,products!$B$2:$B$5,0)),AND($B35="",INDEX(products!$I$2:$I$5,MATCH(H$1,products!$B$2:$B$5,0))=1))),1,0) -> 1 | I35: =IFERROR(INDEX($E$1:$H$1,MATCH(1,E35:H35,0)),"No offer") -> Standard
A36: 5035 | C36: 9000000 | D36: 0 | E36: =IF(AND($D36<=90,$C36>=INDEX(products!$D$2:$D$5,MATCH(E$1,products!$B$2:$B$5,0)),OR($B36>=INDEX(products!$C$2:$C$5,MATCH(E$1,products!$B$2:$B$5,0)),AND($B36="",INDEX(products!$I$2:$I$5,MATCH(E$1,products!$B$2:$B$5,0))=1))),1,0) -> 0 | F36: =IF(AND($D36<=90,$C36>=INDEX(products!$D$2:$D$5,MATCH(F$1,products!$B$2:$B$5,0)),OR($B36>=INDEX(products!$C$2:$C$5,MATCH(F$1,products!$B$2:$B$5,0)),AND($B36="",INDEX(products!$I$2:$I$5,MATCH(F$1,products!$B$2:$B$5,0))=1))),1,0) -> 0 | G36: =IF(AND($D36<=90,$C36>=INDEX(products!$D$2:$D$5,MATCH(G$1,products!$B$2:$B$5,0)),OR($B36>=INDEX(products!$C$2:$C$5,MATCH(G$1,products!$B$2:$B$5,0)),AND($B36="",INDEX(products!$I$2:$I$5,MATCH(G$1,products!$B$2:$B$5,0))=1))),1,0) -> 0 | H36: =IF(AND($D36<=90,$C36>=INDEX(products!$D$2:$D$5,MATCH(H$1,products!$B$2:$B$5,0)),OR($B36>=INDEX(products!$C$2:$C$5,MATCH(H$1,products!$B$2:$B$5,0)),AND($B36="",INDEX(products!$I$2:$I$5,MATCH(H$1,products!$B$2:$B$5,0))=1))),1,0) -> 1 | I36: =IFERROR(INDEX($E$1:$H$1,MATCH(1,E36:H36,0)),"No offer") -> Micro
A37: 5036 | B37: 562 | C37: 11000000 | D37: 37 | E37: =IF(AND($D37<=90,$C37>=INDEX(products!$D$2:$D$5,MATCH(E$1,products!$B$2:$B$5,0)),OR($B37>=INDEX(products!$C$2:$C$5,MATCH(E$1,products!$B$2:$B$5,0)),AND($B37="",INDEX(products!$I$2:$I$5,MATCH(E$1,products!$B$2:$B$5,0))=1))),1,0) -> 0 | F37: =IF(AND($D37<=90,$C37>=INDEX(products!$D$2:$D$5,MATCH(F$1,products!$B$2:$B$5,0)),OR($B37>=INDEX(products!$C$2:$C$5,MATCH(F$1,products!$B$2:$B$5,0)),AND($B37="",INDEX(products!$I$2:$I$5,MATCH(F$1,products!$B$2:$B$5,0))=1))),1,0) -> 0 | G37: =IF(AND($D37<=90,$C37>=INDEX(products!$D$2:$D$5,MATCH(G$1,products!$B$2:$B$5,0)),OR($B37>=INDEX(products!$C$2:$C$5,MATCH(G$1,products!$B$2:$B$5,0)),AND($B37="",INDEX(products!$I$2:$I$5,MATCH(G$1,products!$B$2:$B$5,0))=1))),1,0) -> 1 | H37: =IF(AND($D37<=90,$C37>=INDEX(products!$D$2:$D$5,MATCH(H$1,products!$B$2:$B$5,0)),OR($B37>=INDEX(products!$C$2:$C$5,MATCH(H$1,products!$B$2:$B$5,0)),AND($B37="",INDEX(products!$I$2:$I$5,MATCH(H$1,products!$B$2:$B$5,0))=1))),1,0) -> 1 | I37: =IFERROR(INDEX($E$1:$H$1,MATCH(1,E37:H37,0)),"No offer") -> Starter
A38: 5037 | B38: 600 | C38: 10000000 | D38: 7 | E38: =IF(AND($D38<=90,$C38>=INDEX(products!$D$2:$D$5,MATCH(E$1,products!$B$2:$B$5,0)),OR($B38>=INDEX(products!$C$2:$C$5,MATCH(E$1,products!$B$2:$B$5,0)),AND($B38="",INDEX(products!$I$2:$I$5,MATCH(E$1,products!$B$2:$B$5,0))=1))),1,0) -> 0 | F38: =IF(AND($D38<=90,$C38>=INDEX(products!$D$2:$D$5,MATCH(F$1,products!$B$2:$B$5,0)),OR($B38>=INDEX(products!$C$2:$C$5,MATCH(F$1,products!$B$2:$B$5,0)),AND($B38="",INDEX(products!$I$2:$I$5,MATCH(F$1,products!$B$2:$B$5,0))=1))),1,0) -> 1 | G38: =IF(AND($D38<=90,$C38>=INDEX(products!$D$2:$D$5,MATCH(G$1,products!$B$2:$B$5,0)),OR($B38>=INDEX(products!$C$2:$C$5,MATCH(G$1,products!$B$2:$B$5,0)),AND($B38="",INDEX(products!$I$2:$I$5,MATCH(G$1,products!$B$2:$B$5,0))=1))),1,0) -> 1 | H38: =IF(AND($D38<=90,$C38>=INDEX(products!$D$2:$D$5,MATCH(H$1,products!$B$2:$B$5,0)),OR($B38>=INDEX(products!$C$2:$C$5,MATCH(H$1,products!$B$2:$B$5,0)),AND($B38="",INDEX(products!$I$2:$I$5,MATCH(H$1,products!$B$2:$B$5,0))=1))),1,0) -> 1 | I38: =IFERROR(INDEX($E$1:$H$1,MATCH(1,E38:H38,0)),"No offer") -> Standard
A39: 5038 | B39: 818 | C39: 6500000 | D39: 2 | E39: =IF(AND($D39<=90,$C39>=INDEX(products!$D$2:$D$5,MATCH(E$1,products!$B$2:$B$5,0)),OR($B39>=INDEX(products!$C$2:$C$5,MATCH(E$1,products!$B$2:$B$5,0)),AND($B39="",INDEX(products!$I$2:$I$5,MATCH(E$1,products!$B$2:$B$5,0))=1))),1,0) -> 0 | F39: =IF(AND($D39<=90,$C39>=INDEX(products!$D$2:$D$5,MATCH(F$1,products!$B$2:$B$5,0)),OR($B39>=INDEX(products!$C$2:$C$5,MATCH(F$1,products!$B$2:$B$5,0)),AND($B39="",INDEX(products!$I$2:$I$5,MATCH(F$1,products!$B$2:$B$5,0))=1))),1,0) -> 0 | G39: =IF(AND($D39<=90,$C39>=INDEX(products!$D$2:$D$5,MATCH(G$1,products!$B$2:$B$5,0)),OR($B39>=INDEX(products!$C$2:$C$5,MATCH(G$1,products!$B$2:$B$5,0)),AND($B39="",INDEX(products!$I$2:$I$5,MATCH(G$1,products!$B$2:$B$5,0))=1))),1,0) -> 0 | H39: =IF(AND($D39<=90,$C39>=INDEX(products!$D$2:$D$5,MATCH(H$1,products!$B$2:$B$5,0)),OR($B39>=INDEX(products!$C$2:$C$5,MATCH(H$1,products!$B$2:$B$5,0)),AND($B39="",INDEX(products!$I$2:$I$5,MATCH(H$1,products!$B$2:$B$5,0))=1))),1,0) -> 1 | I39: =IFERROR(INDEX($E$1:$H$1,MATCH(1,E39:H39,0)),"No offer") -> Micro
